Workbook
Name Dynamic_SalesReps: Target_Chart_Data!$D$2:INDEX(Target_Chart_Data!$D$2:$D$21,COUNTIF(Target_Chart_Data!$D$2:$D$21,"Sales Rep*"))
Name Dynamic_TargetRates: Target_Chart_Data!$E$2:INDEX(Target_Chart_Data!$E$2:$E$21,COUNTIF(Target_Chart_Data!$D$2:$D$21,"Sales Rep*"))
Name Slicer_Sales_Rep_Region: #N/A

Sheet sales_activities
A1: activity_id | B1: opportunity_id | C1: rep_id | D1: activity_date | E1: activity_type | F1: outcome
A2: A000001 | B2: O00001 | C2: R008 | D2: 45905 | E2: Meeting | F2: Next step scheduled
A3: A000002 | B3: O00001 | C3: R008 | D3: 45923 | E3: Demo | F3: Next step scheduled
A4: A000003 | B4: O00001 | C4: R008 | D4: 45910 | E4: Follow-up | F4: Next step scheduled
A5: A000004 | B5: O00001 | C5: R008 | D5: 45917 | E5: Meeting | F5: Next step scheduled
A6: A000005 | B6: O00002 | C6: R014 | D6: 45674 | E6: Follow-up | F6: Next step scheduled
A7: A000006 | B7: O00002 | C7: R014 | D7: 45673 | E7: Call | F7: Next step scheduled
A8: A000007 | B8: O00002 | C8: R014 | D8: 45681 | E8: Email | F8: Next step scheduled
A9: A000008 | B9: O00002 | C9: R014 | D9: 45686 | E9: Follow-up | F9: Customer responded
A10: A000009 | B10: O00002 | C10: R014 | D10: 45670 | E10: Email | F10: Completed
A11: A000010 | B11: O00003 | C11: R006 | D11: 45781 | E11: Follow-up | F11: Next step scheduled
A12: A000011 | B12: O00003 | C12: R006 | D12: 45785 | E12: Call | F12: Next step scheduled
A13: A000012 | B13: O00003 | C13: R006 | D13: 45763 | E13: Follow-up | F13: Completed
... A10483: A010482 | B10483: O03000 | C10483: R006 | D10483: 45935 | E10483: Demo | F10483: Customer responded

Sheet sales_reps
A1: rep_id | B1: rep_name | C1: region | D1: team | E1: annual_target_inr
A2: R001 | B2: Sales Rep 01 | C2: South | D2: South Sales | E2: 12000000
A3: R002 | B3: Sales Rep 02 | C3: South | D3: South Sales | E3: 15000000
A4: R003 | B4: Sales Rep 03 | C4: South | D4: South Sales | E4: 18000000
A5: R004 | B5: Sales Rep 04 | C5: South | D5: South Sales | E5: 18000000
A6: R005 | B6: Sales Rep 05 | C6: South | D6: South Sales | E6: 12000000
A7: R006 | B7: Sales Rep 06 | C7: North | D7: North Sales | E7: 21000000
A8: R007 | B8: Sales Rep 07 | C8: North | D8: North Sales | E8: 21000000
A9: R008 | B9: Sales Rep 08 | C9: North | D9: North Sales | E9: 18000000
A10: R009 | B10: Sales Rep 09 | C10: North | D10: North Sales | E10: 12000000
A11: R010 | B11: Sales Rep 10 | C11: North | D11: North Sales | E11: 15000000
A12: R011 | B12: Sales Rep 11 | C12: West | D12: West Sales | E12: 12000000
A13: R012 | B13: Sales Rep 12 | C13: West | D13: West Sales | E13: 21000000
... A21: R020 | B21: Sales Rep 20 | C21: East | D21: East Sales | E21: 12000000

Sheet products
A1: product_id | B1: product_name | C1: category | D1: annual_list_price_inr
A2: P001 | B2: CRM Essentials | C2: CRM | D2: 120000
A3: P002 | B3: CRM Enterprise | C3: CRM | D3: 420000
A4: P003 | B4: Workflow Automate | C4: Automation | D4: 240000
A5: P004 | B5: Analytics Cloud | C5: Analytics | D5: 300000
A6: P005 | B6: Support Desk | C6: Service | D6: 180000
A7: P006 | B7: Security Suite | C7: Security | D7: 360000

Sheet customers
A1: customer_id | B1: customer_name | C1: industry | D1: segment | E1: region | F1: city
A2: C0001 | B2: Nexa Client 0001 | C2: Banking | D2: Mid-Market | E2: South | F2: Chennai
A3: C0002 | B3: Nexa Client 0002 | C3: Retail | D3: Mid-Market | E3: North | F3: Noida
A4: C0003 | B4: Nexa Client 0003 | C4: Technology | D4: SMB | E4: South | F4: Chennai
A5: C0004 | B5: Nexa Client 0004 | C5: Retail | D5: SMB | E5: South | F5: Hyderabad
A6: C0005 | B6: Nexa Client 0005 | C6: Technology | D6: SMB | E6: South | F6: Hyderabad
A7: C0006 | B7: Nexa Client 0006 | C7: Retail | D7: SMB | E7: East | F7: Bhubaneswar
A8: C0007 | B8: Nexa Client 0007 | C8: Retail | D8: Mid-Market | E8: South | F8: Bengaluru
A9: C0008 | B9: Nexa Client 0008 | C9: Retail | D9: SMB | E9: West | F9: Pune
A10: C0009 | B10: Nexa Client 0009 | C10: Banking | D10: SMB | E10: South | F10: Bengaluru
A11: C0010 | B11: Nexa Client 0010 | C11: Technology | D11: SMB | E11: West | F11: Mumbai
A12: C0011 | B12: Nexa Client 0011 | C12: Technology | D12: SMB | E12: East | F12: Bhubaneswar
... A501: C0500 | B501: Nexa Client 0500 | C501: Manufacturing | D501: SMB | E501: West | F501: Pune

Sheet Regional_Analysis
A1: stage | B1: Won
A3: Row Labels | B3: Sum of deal_value_inr
A4: South | B4: 91335000
A5: West | B5: 88860000
A6: North | B6: 85695000
A7: East | B7: 77607000
A8: Grand Total | B8: 343497000

Sheet Regional_WinRate
A3: Count of opportunity_id | B3: Column Labels
A4: Row Labels | B4: Lost | C4: Open | D4: Won | E4: Grand Total | F4: Win Rate | H4: Region | I4: Win Rate
A5: East | B5: 247 | C5: 248 | D5: 195 | E5: 690 | F5: =IFERROR(D5/(B5+D5),0) -> 0.44117647 | H5: East | I5: =F5 -> 0.44117647
A6: North | B6: 247 | C6: 256 | D6: 229 | E6: 732 | F6: =IFERROR(D6/(B6+D6),0) -> 0.48109244 | H6: North | I6: =F6 -> 0.48109244
A7: South | B7: 277 | C7: 256 | D7: 249 | E7: 782 | F7: =IFERROR(D7/(B7+D7),0) -> 0.47338403 | H7: South | I7: =F7 -> 0.47338403
A8: West | B8: 296 | C8: 266 | D8: 234 | E8: 796 | F8: =IFERROR(D8/(B8+D8),0) -> 0.44150943 | H8: West | I8: =F8 -> 0.44150943
A9: Grand Total | B9: 1067 | C9: 1026 | D9: 907 | E9: 3000 | F9: =IFERROR(D9/(B9+D9),0) -> 0.45947315

Sheet Product_Analysis
A1: stage | B1: Won
A3: Row Labels | B3: Sum of deal_value_inr
A4: Security Suite | B4: 82062000
A5: CRM Enterprise | B5: 73185000
A6: Analytics Cloud | B6: 65775000
A7: Workflow Automate | B7: 53448000
A8: Support Desk | B8: 41985000
A9: CRM Essentials | B9: 27042000
A10: Grand Total | B10: 343497000

Sheet Product_WinRate
A3: Count of opportunity_id | B3: Column Labels
A4: Row Labels | B4: Lost | C4: Open | D4: Won | E4: Grand Total | F4: Win Rate | H4: Product Name | I4: Win Rate
A5: Analytics Cloud | B5: 201 | C5: 163 | D5: 153 | E5: 517 | F5: =IFERROR(D5/(B5+D5),0) -> 0.43220339 | H5: Analytics Cloud | I5: =IFERROR(D5/(B5+D5),0) -> 0.43220339
A6: CRM Enterprise | B6: 170 | C6: 168 | D6: 129 | E6: 467 | F6: =IFERROR(D6/(B6+D6),0) -> 0.43143813 | H6: CRM Enterprise | I6: =IFERROR(D6/(B6+D6),0) -> 0.43143813
A7: CRM Essentials | B7: 194 | C7: 171 | D7: 157 | E7: 522 | F7: =IFERROR(D7/(B7+D7),0) -> 0.44729345 | H7: CRM Essentials | I7: =IFERROR(D7/(B7+D7),0) -> 0.44729345
A8: Security Suite | B8: 181 | C8: 168 | D8: 166 | E8: 515 | F8: =IFERROR(D8/(B8+D8),0) -> 0.47838617 | H8: Security Suite | I8: =IFERROR(D8/(B8+D8),0) -> 0.47838617
A9: Support Desk | B9: 152 | C9: 186 | D9: 154 | E9: 492 | F9: =IFERROR(D9/(B9+D9),0) -> 0.50326797 | H9: Support Desk | I9: =IFERROR(D9/(B9+D9),0) -> 0.50326797
A10: Workflow Automate | B10: 169 | C10: 170 | D10: 148 | E10: 487 | F10: =IFERROR(D10/(B10+D10),0) -> 0.46687697 | H10: Workflow Automate | I10: =IFERROR(D10/(B10+D10),0) -> 0.46687697
A11: Grand Total | B11: 1067 | C11: 1026 | D11: 907 | E11: 3000 | F11: =IFERROR(D11/(B11+D11),0) -> 0.45947315

Sheet SalesRep_Performance
A1: stage | B1: Won
A3: Row Labels | B3: Sum of deal_value_inr | D3: Annual Target | E3: Target Achievement % | F3: Performance Status
A4: Sales Rep 05 | B4: 22146000 | D4: =_xlfn.XLOOKUP(A4,tblSalesReps[rep_name],tblSalesReps[annual_target_inr],"Missing") -> 12000000 | E4: =IFERROR(B4/D4,0) -> 1.8455 | F4: =IF(E4>=1.2,"Outstanding",IF(E4>=1,"Achieved",IF(E4>=0.8,"Near Target","Below Target"))) -> Outstanding
A5: Sales Rep 15 | B5: 22086000 | D5: =_xlfn.XLOOKUP(A5,tblSalesReps[rep_name],tblSalesReps[annual_target_inr],"Missing") -> 18000000 | E5: =IFERROR(B5/D5,0) -> 1.227 | F5: =IF(E5>=1.2,"Outstanding",IF(E5>=1,"Achieved",IF(E5>=0.8,"Near Target","Below Target"))) -> Outstanding
A6: Sales Rep 20 | B6: 21186000 | D6: =_xlfn.XLOOKUP(A6,tblSalesReps[rep_name],tblSalesReps[annual_target_inr],"Missing") -> 12000000 | E6: =IFERROR(B6/D6,0) -> 1.7655 | F6: =IF(E6>=1.2,"Outstanding",IF(E6>=1,"Achieved",IF(E6>=0.8,"Near Target","Below Target"))) -> Outstanding
A7: Sales Rep 09 | B7: 20025000 | D7: =_xlfn.XLOOKUP(A7,tblSalesReps[rep_name],tblSalesReps[annual_target_inr],"Missing") -> 12000000 | E7: =IFERROR(B7/D7,0) -> 1.66875 | F7: =IF(E7>=1.2,"Outstanding",IF(E7>=1,"Achieved",IF(E7>=0.8,"Near Target","Below Target"))) -> Outstanding
A8: Sales Rep 04 | B8: 19542000 | D8: =_xlfn.XLOOKUP(A8,tblSalesReps[rep_name],tblSalesReps[annual_target_inr],"Missing") -> 18000000 | E8: =IFERROR(B8/D8,0) -> 1.0856667 | F8: =IF(E8>=1.2,"Outstanding",IF(E8>=1,"Achieved",IF(E8>=0.8,"Near Target","Below Target"))) -> Achieved
A9: Sales Rep 03 | B9: 19299000 | D9: =_xlfn.XLOOKUP(A9,tblSalesReps[rep_name],tblSalesReps[annual_target_inr],"Missing") -> 18000000 | E9: =IFERROR(B9/D9,0) -> 1.0721667 | F9: =IF(E9>=1.2,"Outstanding",IF(E9>=1,"Achieved",IF(E9>=0.8,"Near Target","Below Target"))) -> Achieved
A10: Sales Rep 14 | B10: 19131000 | D10: =_xlfn.XLOOKUP(A10,tblSalesReps[rep_name],tblSalesReps[annual_target_inr],"Missing") -> 18000000 | E10: =IFERROR(B10/D10,0) -> 1.0628333 | F10: =IF(E10>=1.2,"Outstanding",IF(E10>=1,"Achieved",IF(E10>=0.8,"Near Target","Below Target"))) -> Achieved
A11: Sales Rep 06 | B11: 18090000 | D11: =_xlfn.XLOOKUP(A11,tblSalesReps[rep_name],tblSalesReps[annual_target_inr],"Missing") -> 21000000 | E11: =IFERROR(B11/D11,0) -> 0.86142857 | F11: =IF(E11>=1.2,"Outstanding",IF(E11>=1,"Achieved",IF(E11>=0.8,"Near Target","Below Target"))) -> Near Target
A12: Sales Rep 12 | B12: 17625000 | D12: =_xlfn.XLOOKUP(A12,tblSalesReps[rep_name],tblSalesReps[annual_target_inr],"Missing") -> 21000000 | E12: =IFERROR(B12/D12,0) -> 0.83928571 | F12: =IF(E12>=1.2,"Outstanding",IF(E12>=1,"Achieved",IF(E12>=0.8,"Near Target","Below Target"))) -> Near Target
A13: Sales Rep 10 | B13: 16440000 | D13: =_xlfn.XLOOKUP(A13,tblSalesReps[rep_name],tblSalesReps[annual_target_inr],"Missing") -> 15000000 | E13: =IFERROR(B13/D13,0) -> 1.096 | F13: =IF(E13>=1.2,"Outstanding",IF(E13>=1,"Achieved",IF(E13>=0.8,"Near Target","Below Target"))) -> Achieved
A14: Sales Rep 02 | B14: 16398000 | D14: =_xlfn.XLOOKUP(A14,tblSalesReps[rep_name],tblSalesReps[annual_target_inr],"Missing") -> 15000000 | E14: =IFERROR(B14/D14,0) -> 1.0932 | F14: =IF(E14>=1.2,"Outstanding",IF(E14>=1,"Achieved",IF(E14>=0.8,"Near Target","Below Target"))) -> Achieved
A15: Sales Rep 19 | B15: 16212000 | D15: =_xlfn.XLOOKUP(A15,tblSalesReps[rep_name],tblSalesReps[annual_target_inr],"Missing") -> 12000000 | E15: =IFERROR(B15/D15,0) -> 1.351 | F15: =IF(E15>=1.2,"Outstanding",IF(E15>=1,"Achieved",IF(E15>=0.8,"Near Target","Below Target"))) -> Outstanding
... A23: Sales Rep 18 | B23: 12996000 | D23: =_xlfn.XLOOKUP(A23,tblSalesReps[rep_name],tblSalesReps[annual_target_inr],"Missing") -> 21000000 | E23: =IFERROR(B23/D23,0) -> 0.61885714 | F23: =IF(E23>=1.2,"Outstanding",IF(E23>=1,"Achieved",IF(E23>=0.8,"Near Target","Below Target"))) -> Below Target
A24: Grand Total | B24: 343497000 | D24: =SUM(D4:INDEX(D:D,MATCH("Grand Total",A:A,0)-1)) -> 324000000 | E24: =IFERROR(INDEX(B:B,MATCH("Grand Total",A:A,0))/D24,0) -> 1.0601759

Sheet Target_Chart_Data
A1: Sales Representative | B1: Target Achievement % | D1: Sales Representative | E1: Target Achievement %
A2: =SalesRep_Performance!A4 -> Sales Rep 05 | B2: =SalesRep_Performance!E4 -> 1.8455 | D2: {=_xlfn._xlws.FILTER(A2:B21,(A2:A21<>"")*(A2:A21<>"Grand Total")*(A2:A21<>0))} -> Sales Rep 05 | E2: 1.8455
A3: =SalesRep_Performance!A5 -> Sales Rep 15 | B3: =SalesRep_Performance!E5 -> 1.227 | D3: Sales Rep 15 | E3: 1.227
A4: =SalesRep_Performance!A6 -> Sales Rep 20 | B4: =SalesRep_Performance!E6 -> 1.7655 | D4: Sales Rep 20 | E4: 1.7655
A5: =SalesRep_Performance!A7 -> Sales Rep 09 | B5: =SalesRep_Performance!E7 -> 1.66875 | D5: Sales Rep 09 | E5: 1.66875
A6: =SalesRep_Performance!A8 -> Sales Rep 04 | B6: =SalesRep_Performance!E8 -> 1.0856667 | D6: Sales Rep 04 | E6: 1.0856667
A7: =SalesRep_Performance!A9 -> Sales Rep 03 | B7: =SalesRep_Performance!E9 -> 1.0721667 | D7: Sales Rep 03 | E7: 1.0721667
A8: =IF(OR(SalesRep_Performance!A10="",SalesRep_Performance!A10=0,SalesRep_Performance!A10="Grand Total"),"",SalesRep_Performance!A10) -> Sales Rep 14 | B8: =IF(A8="","",SalesRep_Performance!E10) -> 1.0628333 | D8: Sales Rep 14 | E8: 1.0628333
A9: =IF(OR(SalesRep_Performance!A11="",SalesRep_Performance!A11=0,SalesRep_Performance!A11="Grand Total"),"",SalesRep_Performance!A11) -> Sales Rep 06 | B9: =IF(A9="","",SalesRep_Performance!E11) -> 0.86142857 | D9: Sales Rep 06 | E9: 0.86142857
A10: =IF(OR(SalesRep_Performance!A12="",SalesRep_Performance!A12=0,SalesRep_Performance!A12="Grand Total"),"",SalesRep_Performance!A12) -> Sales Rep 12 | B10: =IF(A10="","",SalesRep_Performance!E12) -> 0.83928571 | D10: Sales Rep 12 | E10: 0.83928571
A11: =IF(OR(SalesRep_Performance!A13="",SalesRep_Performance!A13=0,SalesRep_Performance!A13="Grand Total"),"",SalesRep_Performance!A13) -> Sales Rep 10 | B11: =IF(A11="","",SalesRep_Performance!E13) -> 1.096 | D11: Sales Rep 10 | E11: 1.096
A12: =IF(OR(SalesRep_Performance!A14="",SalesRep_Performance!A14=0,SalesRep_Performance!A14="Grand Total"),"",SalesRep_Performance!A14) -> Sales Rep 02 | B12: =IF(A12="","",SalesRep_Performance!E14) -> 1.0932 | D12: Sales Rep 02 | E12: 1.0932
A13: =IF(OR(SalesRep_Performance!A15="",SalesRep_Performance!A15=0,SalesRep_Performance!A15="Grand Total"),"",SalesRep_Performance!A15) -> Sales Rep 19 | B13: =IF(A13="","",SalesRep_Performance!E15) -> 1.351 | D13: Sales Rep 19 | E13: 1.351
A14: =IF(OR(SalesRep_Performance!A16="",SalesRep_Performance!A16=0,SalesRep_Performance!A16="Grand Total"),"",SalesRep_Performance!A16) -> Sales Rep 13 | B14: =IF(A14="","",SalesRep_Performance!E16) -> 0.89933333 | D14: Sales Rep 13 | E14: 0.89933333
A15: =IF(OR(SalesRep_Performance!A17="",SalesRep_Performance!A17=0,SalesRep_Performance!A17="Grand Total"),"",SalesRep_Performance!A17) -> Sales Rep 08 | B15: =IF(A15="","",SalesRep_Performance!E17) -> 0.878 | D15: Sales Rep 08 | E15: 0.878
A16: =IF(OR(SalesRep_Performance!A18="",SalesRep_Performance!A18=0,SalesRep_Performance!A18="Grand Total"),"",SalesRep_Performance!A18) -> Sales Rep 07 | B16: =IF(A16="","",SalesRep_Performance!E18) -> 0.73028571 | D16: Sales Rep 07 | E16: 0.73028571
A17: =IF(OR(SalesRep_Performance!A19="",SalesRep_Performance!A19=0,SalesRep_Performance!A19="Grand Total"),"",SalesRep_Performance!A19) -> Sales Rep 16 | B17: =IF(A17="","",SalesRep_Performance!E19) -> 0.938 | D17: Sales Rep 16 | E17: 0.938
A18: =IF(OR(SalesRep_Performance!A20="",SalesRep_Performance!A20=0,SalesRep_Performance!A20="Grand Total"),"",SalesRep_Performance!A20) -> Sales Rep 01 | B18: =IF(A18="","",SalesRep_Performance!E20) -> 1.1625 | D18: Sales Rep 01 | E18: 1.1625
A19: =IF(OR(SalesRep_Performance!A21="",SalesRep_Performance!A21=0,SalesRep_Performance!A21="Grand Total"),"",SalesRep_Performance!A21) -> Sales Rep 11 | B19: =IF(A19="","",SalesRep_Performance!E21) -> 1.1525 | D19: Sales Rep 11 | E19: 1.1525
... A21: =IF(OR(SalesRep_Performance!A23="",SalesRep_Performance!A23=0,SalesRep_Performance!A23="Grand Total"),"",SalesRep_Performance!A23) -> Sales Rep 18 | B21: =IF(A21="","",SalesRep_Performance!E23) -> 0.61885714 | D21: Sales Rep 18 | E21: 0.61885714

Sheet Sales_Dashboard
A1: REVENUE & SALES OPERATIONS INTELLIGENCE
A2: Sales Performance Dashboard | 2025–2026
A4: Total Opportunities | D4: Won Opportunities | G4: Closed Opportunity Win Rate | J4: Won Revenue | M4: Target Achievement
A5: =IFERROR(GETPIVOTDATA("Count of opportunity_id",Region_Opportunity_Count!$A$3),0) -> 3000 | D5: =IFERROR(GETPIVOTDATA("Count of opportunity_id",Region_Won_Count!$A$3),0) -> 907 | G5: =IFERROR(D5/GETPIVOTDATA("Count of opportunity_id",Region_Closed_Count!$A$3),0) -> 0.45947315 | J5: =IFERROR(INDEX(SalesRep_Performance!B:B,MATCH("Grand Total",SalesRep_Performance!A:A,0)),0) -> 343497000 | L5: =SalesRep_Performance!E24 -> 1.0601759
Q15: BUSINESS PERFORMANCE INSIGHTS | X15: =IFERROR(INDEX(Regional_Analysis!$A$4:$A$7,MATCH(MAX(Regional_Analysis!$B$4:$B$7),Regional_Analysis!$B$4:$B$7,0)),"") -> South
X16: =IFERROR(MAX(Regional_Analysis!$B$4:$B$7),0) -> 91335000
Q17: Top Revenue Region | X17: =IF(X15="","No data",X15&" — ₹"&TEXT(X16/1000000,"0.0")&"M") -> South — ₹91.3M
Q18: =X17 -> South — ₹91.3M
X19: =IFERROR(INDEX(Product_Analysis!$A$4:$A$9,MATCH(MAX(Product_Analysis!$B$4:$B$9),Product_Analysis!$B$4:$B$9,0)),"") -> Security Suite
Q20: Top Revenue Product | X20: =IFERROR(MAX(Product_Analysis!$B$4:$B$9),0) -> 82062000
Q21: =X21 -> Security Suite — ₹82.1M | X21: =IF(X19="","No data",X19&" — ₹"&TEXT(X20/1000000,"0.0")&"M") -> Security Suite — ₹82.1M
Q23: Closed Opportunity Win Rate
Q24: =G5 -> 0.45947315
Q26: Target Achievement
Q27: =L5 -> 1.0601759

Sheet SalesRep_WinRate
A3: Count of opportunity_id | B3: Column Labels
A4: Row Labels | B4: Lost | C4: Open | D4: Won | E4: Grand Total | F4: Win Rate
A5: Sales Rep 01 | B5: 62 | C5: 52 | D5: 44 | E5: 158 | F5: =IFERROR(D5/(B5+D5),0) -> 0.41509434
A6: Sales Rep 02 | B6: 61 | C6: 56 | D6: 44 | E6: 161 | F6: =IFERROR(D6/(B6+D6),0) -> 0.41904762
A7: Sales Rep 03 | B7: 57 | C7: 48 | D7: 53 | E7: 158 | F7: =IFERROR(D7/(B7+D7),0) -> 0.48181818
A8: Sales Rep 04 | B8: 47 | C8: 54 | D8: 53 | E8: 154 | F8: =IFERROR(D8/(B8+D8),0) -> 0.53
A9: Sales Rep 05 | B9: 50 | C9: 46 | D9: 55 | E9: 151 | F9: =IFERROR(D9/(B9+D9),0) -> 0.52380952
A10: Sales Rep 06 | B10: 53 | C10: 59 | D10: 48 | E10: 160 | F10: =IFERROR(D10/(B10+D10),0) -> 0.47524752
A11: Sales Rep 07 | B11: 44 | C11: 52 | D11: 50 | E11: 146 | F11: =IFERROR(D11/(B11+D11),0) -> 0.53191489
A12: Sales Rep 08 | B12: 57 | C12: 43 | D12: 41 | E12: 141 | F12: =IFERROR(D12/(B12+D12),0) -> 0.41836735
A13: Sales Rep 09 | B13: 55 | C13: 56 | D13: 46 | E13: 157 | F13: =IFERROR(D13/(B13+D13),0) -> 0.45544554
A14: Sales Rep 10 | B14: 38 | C14: 46 | D14: 44 | E14: 128 | F14: =IFERROR(D14/(B14+D14),0) -> 0.53658537
A15: Sales Rep 11 | B15: 74 | C15: 52 | D15: 41 | E15: 167 | F15: =IFERROR(D15/(B15+D15),0) -> 0.35652174
A16: Sales Rep 12 | B16: 55 | C16: 63 | D16: 45 | E16: 163 | F16: =IFERROR(D16/(B16+D16),0) -> 0.45
... A25: Grand Total | B25: 1067 | C25: 1026 | D25: 907 | E25: 3000 | F25: =IFERROR(D25/(B25+D25),0) -> 0.45947315

Sheet Region_Opportunity_Count
A3: Row Labels | B3: Count of opportunity_id
A4: East | B4: 690
A5: North | B5: 732
A6: South | B6: 782
A7: West | B7: 796
A8: Grand Total | B8: 3000

Sheet Region_Won_Count
A1: stage | B1: Won
A3: Row Labels | B3: Count of opportunity_id
A4: East | B4: 195
A5: North | B5: 229
A6: South | B6: 249
A7: West | B7: 234
A8: Grand Total | B8: 907

Sheet Region_Closed_Count
A1: stage | B1: (Multiple Items)
A3: Row Labels | B3: Count of opportunity_id
A4: East | B4: 442
A5: North | B5: 476
A6: South | B6: 526
A7: West | B7: 530
A8: Grand Total | B8: 1974

Sheet opportunities
A1: opportunity_id | B1: customer_id | C1: product_id | D1: rep_id | E1: created_date | F1: expected_close_date | G1: actual_close_date | H1: stage | I1: units | J1: discount_pct | K1: deal_value_inr | L1: probability_pct | M1: lost_reason | N1: Customer Region | O1: Product Name | P1: Product Category | Q1: Sales Rep Name | R1: Sales Rep Region
A2: O00001 | B2: C0020 | C2: P002 | D2: R008 | E2: 45900 | F2: 45926 | G2: 45926 | H2: Lost | I2: 3 | J2: 20 | K2: 1008000 | L2: 0 | M2: Budget | N2: =_xlfn.XLOOKUP(B2,tblCustomers[customer_id],tblCustomers[region],"Missing") -> North | O2: =_xlfn.XLOOKUP(C2,tblProducts[product_id],tblProducts[product_name],"Missing") -> CRM Enterprise | P2: =_xlfn.XLOOKUP(C2,tblProducts[product_id],tblProducts[category],"Missing") -> CRM | Q2: =_xlfn.XLOOKUP(D2,tblSalesReps[rep_id],tblSalesReps[rep_name],"Missing") -> Sales Rep 08 | R2: =_xlfn.XLOOKUP(D2,tblSalesReps[rep_id],tblSalesReps[region],"Missing") -> North
A3: O00002 | B3: C0289 | C3: P003 | D3: R014 | E3: 45666 | F3: 45687 | G3: 45687 | H3: Lost | I3: 2 | J3: 20 | K3: 384000 | L3: 0 | M3: Price | N3: =_xlfn.XLOOKUP(B3,tblCustomers[customer_id],tblCustomers[region],"Missing") -> West | O3: =_xlfn.XLOOKUP(C3,tblProducts[product_id],tblProducts[product_name],"Missing") -> Workflow Automate | P3: =_xlfn.XLOOKUP(C3,tblProducts[product_id],tblProducts[category],"Missing") -> Automation | Q3: =_xlfn.XLOOKUP(D3,tblSalesReps[rep_id],tblSalesReps[rep_name],"Missing") -> Sales Rep 14 | R3: =_xlfn.XLOOKUP(D3,tblSalesReps[rep_id],tblSalesReps[region],"Missing") -> West
A4: O00003 | B4: C0294 | C4: P006 | D4: R006 | E4: 45755 | F4: 45802 | G4: 45802 | H4: Won | I4: 2 | J4: 5 | K4: 684000 | L4: 100 | N4: =_xlfn.XLOOKUP(B4,tblCustomers[customer_id],tblCustomers[region],"Missing") -> North | O4: =_xlfn.XLOOKUP(C4,tblProducts[product_id],tblProducts[product_name],"Missing") -> Security Suite | P4: =_xlfn.XLOOKUP(C4,tblProducts[product_id],tblProducts[category],"Missing") -> Security | Q4: =_xlfn.XLOOKUP(D4,tblSalesReps[rep_id],tblSalesReps[rep_name],"Missing") -> Sales Rep 06 | R4: =_xlfn.XLOOKUP(D4,tblSalesReps[rep_id],tblSalesReps[region],"Missing") -> North
A5: O00004 | B5: C0288 | C5: P003 | D5: R004 | E5: 45927 | F5: 45956 | G5: 45956 | H5: Lost | I5: 2 | J5: 20 | K5: 384000 | L5: 0 | M5: Feature gap | N5: =_xlfn.XLOOKUP(B5,tblCustomers[customer_id],tblCustomers[region],"Missing") -> South | O5: =_xlfn.XLOOKUP(C5,tblProducts[product_id],tblProducts[product_name],"Missing") -> Workflow Automate | P5: =_xlfn.XLOOKUP(C5,tblProducts[product_id],tblProducts[category],"Missing") -> Automation | Q5: =_xlfn.XLOOKUP(D5,tblSalesReps[rep_id],tblSalesReps[rep_name],"Missing") -> Sales Rep 04 | R5: =_xlfn.XLOOKUP(D5,tblSalesReps[rep_id],tblSalesReps[region],"Missing") -> South
A6: O00005 | B6: C0361 | C6: P002 | D6: R009 | E6: 45820 | F6: 45898 | G6: 45898 | H6: Lost | I6: 1 | J6: 10 | K6: 378000 | L6: 0 | M6: Feature gap | N6: =_xlfn.XLOOKUP(B6,tblCustomers[customer_id],tblCustomers[region],"Missing") -> North | O6: =_xlfn.XLOOKUP(C6,tblProducts[product_id],tblProducts[product_name],"Missing") -> CRM Enterprise | P6: =_xlfn.XLOOKUP(C6,tblProducts[product_id],tblProducts[category],"Missing") -> CRM | Q6: =_xlfn.XLOOKUP(D6,tblSalesReps[rep_id],tblSalesReps[rep_name],"Missing") -> Sales Rep 09 | R6: =_xlfn.XLOOKUP(D6,tblSalesReps[rep_id],tblSalesReps[region],"Missing") -> North
A7: O00006 | B7: C0478 | C7: P005 | D7: R013 | E7: 45728 | F7: 45810 | G7: 45810 | H7: Won | I7: 1 | J7: 5 | K7: 171000 | L7: 100 | N7: =_xlfn.XLOOKUP(B7,tblCustomers[customer_id],tblCustomers[region],"Missing") -> West | O7: =_xlfn.XLOOKUP(C7,tblProducts[product_id],tblProducts[product_name],"Missing") -> Support Desk | P7: =_xlfn.XLOOKUP(C7,tblProducts[product_id],tblProducts[category],"Missing") -> Service | Q7: =_xlfn.XLOOKUP(D7,tblSalesReps[rep_id],tblSalesReps[rep_name],"Missing") -> Sales Rep 13 | R7: =_xlfn.XLOOKUP(D7,tblSalesReps[rep_id],tblSalesReps[region],"Missing") -> West
A8: O00007 | B8: C0395 | C8: P002 | D8: R006 | E8: 45939 | F8: 45966 | H8: Open | I8: 2 | J8: 15 | K8: 714000 | L8: 80 | N8: =_xlfn.XLOOKUP(B8,tblCustomers[customer_id],tblCustomers[region],"Missing") -> North | O8: =_xlfn.XLOOKUP(C8,tblProducts[product_id],tblProducts[product_name],"Missing") -> CRM Enterprise | P8: =_xlfn.XLOOKUP(C8,tblProducts[product_id],tblProducts[category],"Missing") -> CRM | Q8: =_xlfn.XLOOKUP(D8,tblSalesReps[rep_id],tblSalesReps[rep_name],"Missing") -> Sales Rep 06 | R8: =_xlfn.XLOOKUP(D8,tblSalesReps[rep_id],tblSalesReps[region],"Missing") -> North
A9: O00008 | B9: C0274 | C9: P006 | D9: R001 | E9: 45747 | F9: 45776 | G9: 45776 | H9: Lost | I9: 1 | J9: 15 | K9: 306000 | L9: 0 | M9: Competition | N9: =_xlfn.XLOOKUP(B9,tblCustomers[customer_id],tblCustomers[region],"Missing") -> South | O9: =_xlfn.XLOOKUP(C9,tblProducts[product_id],tblProducts[product_name],"Missing") -> Security Suite | P9: =_xlfn.XLOOKUP(C9,tblProducts[product_id],tblProducts[category],"Missing") -> Security | Q9: =_xlfn.XLOOKUP(D9,tblSalesReps[rep_id],tblSalesReps[rep_name],"Missing") -> Sales Rep 01 | R9: =_xlfn.XLOOKUP(D9,tblSalesReps[rep_id],tblSalesReps[region],"Missing") -> South
A10: O00009 | B10: C0253 | C10: P002 | D10: R015 | E10: 45897 | F10: 45918 | G10: 45918 | H10: Won | I10: 1 | J10: 5 | K10: 399000 | L10: 100 | N10: =_xlfn.XLOOKUP(B10,tblCustomers[customer_id],tblCustomers[region],"Missing") -> West | O10: =_xlfn.XLOOKUP(C10,tblProducts[product_id],tblProducts[product_name],"Missing") -> CRM Enterprise | P10: =_xlfn.XLOOKUP(C10,tblProducts[product_id],tblProducts[category],"Missing") -> CRM | Q10: =_xlfn.XLOOKUP(D10,tblSalesReps[rep_id],tblSalesReps[rep_name],"Missing") -> Sales Rep 15 | R10: =_xlfn.XLOOKUP(D10,tblSalesReps[rep_id],tblSalesReps[region],"Missing") -> West
A11: O00010 | B11: C0264 | C11: P003 | D11: R016 | E11: 45863 | F11: 45893 | G11: 45893 | H11: Lost | I11: 1 | J11: 15 | K11: 204000 | L11: 0 | M11: Competition | N11: =_xlfn.XLOOKUP(B11,tblCustomers[customer_id],tblCustomers[region],"Missing") -> East | O11: =_xlfn.XLOOKUP(C11,tblProducts[product_id],tblProducts[product_name],"Missing") -> Workflow Automate | P11: =_xlfn.XLOOKUP(C11,tblProducts[product_id],tblProducts[category],"Missing") -> Automation | Q11: =_xlfn.XLOOKUP(D11,tblSalesReps[rep_id],tblSalesReps[rep_name],"Missing") -> Sales Rep 16 | R11: =_xlfn.XLOOKUP(D11,tblSalesReps[rep_id],tblSalesReps[region],"Missing") -> East
A12: O00011 | B12: C0155 | C12: P005 | D12: R020 | E12: 45663 | F12: 45716 | G12: 45716 | H12: Won | I12: 1 | J12: 0 | K12: 180000 | L12: 100 | N12: =_xlfn.XLOOKUP(B12,tblCustomers[customer_id],tblCustomers[region],"Missing") -> East | O12: =_xlfn.XLOOKUP(C12,tblProducts[product_id],tblProducts[product_name],"Missing") -> Support Desk | P12: =_xlfn.XLOOKUP(C12,tblProducts[product_id],tblProducts[category],"Missing") -> Service | Q12: =_xlfn.XLOOKUP(D12,tblSalesReps[rep_id],tblSalesReps[rep_name],"Missing") -> Sales Rep 20 | R12: =_xlfn.XLOOKUP(D12,tblSalesReps[rep_id],tblSalesReps[region],"Missing") -> East
A13: O00012 | B13: C0491 | C13: P002 | D13: R019 | E13: 45736 | F13: 45820 | G13: 45820 | H13: Lost | I13: 1 | J13: 15 | K13: 357000 | L13: 0 | M13: Feature gap | N13: =_xlfn.XLOOKUP(B13,tblCustomers[customer_id],tblCustomers[region],"Missing") -> East | O13: =_xlfn.XLOOKUP(C13,tblProducts[product_id],tblProducts[product_name],"Missing") -> CRM Enterprise | P13: =_xlfn.XLOOKUP(C13,tblProducts[product_id],tblProducts[category],"Missing") -> CRM | Q13: =_xlfn.XLOOKUP(D13,tblSalesReps[rep_id],tblSalesReps[rep_name],"Missing") -> Sales Rep 19 | R13: =_xlfn.XLOOKUP(D13,tblSalesReps[rep_id],tblSalesReps[region],"Missing") -> East
A14: O00013 | B14: C0058 | C14: P001 | D14: R005 | E14: 45916 | F14: 45991 | G14: 45991 | H14: Won | I14: 1 | J14: 5 | K14: 114000 | L14: 100 | N14: =_xlfn.XLOOKUP(B14,tblCustomers[customer_id],tblCustomers[region],"Missing") -> South | O14: =_xlfn.XLOOKUP(C14,tblProducts[product_id],tblProducts[product_name],"Missing") -> CRM Essentials | P14: =_xlfn.XLOOKUP(C14,tblProducts[product_id],tblProducts[category],"Missing") -> CRM | Q14: =_xlfn.XLOOKUP(D14,tblSalesReps[rep_id],tblSalesReps[rep_name],"Missing") -> Sales Rep 05 | R14: =_xlfn.XLOOKUP(D14,tblSalesReps[rep_id],tblSalesReps[region],"Missing") -> South
A15: O00014 | B15: C0030 | C15: P005 | D15: R019 | E15: 46002 | F15: 46011 | H15: Open | I15: 2 | J15: 10 | K15: 324000 | L15: 20 | N15: =_xlfn.XLOOKUP(B15,tblCustomers[customer_id],tblCustomers[region],"Missing") -> East | O15: =_xlfn.XLOOKUP(C15,tblProducts[product_id],tblProducts[product_name],"Missing") -> Support Desk | P15: =_xlfn.XLOOKUP(C15,tblProducts[product_id],tblProducts[category],"Missing") -> Service | Q15: =_xlfn.XLOOKUP(D15,tblSalesReps[rep_id],tblSalesReps[rep_name],"Missing") -> Sales Rep 19 | R15: =_xlfn.XLOOKUP(D15,tblSalesReps[rep_id],tblSalesReps[region],"Missing") -> East
A16: O00015 | B16: C0479 | C16: P001 | D16: R004 | E16: 45674 | F16: 45704 | G16: 45704 | H16: Won | I16: 1 | J16: 15 | K16: 102000 | L16: 100 | N16: =_xlfn.XLOOKUP(B16,tblCustomers[customer_id],tblCustomers[region],"Missing") -> South | O16: =_xlfn.XLOOKUP(C16,tblProducts[product_id],tblProducts[product_name],"Missing") -> CRM Essentials | P16: =_xlfn.XLOOKUP(C16,tblProducts[product_id],tblProducts[category],"Missing") -> CRM | Q16: =_xlfn.XLOOKUP(D16,tblSalesReps[rep_id],tblSalesReps[rep_name],"Missing") -> Sales Rep 04 | R16: =_xlfn.XLOOKUP(D16,tblSalesReps[rep_id],tblSalesReps[region],"Missing") -> South
A17: O00016 | B17: C0115 | C17: P001 | D17: R011 | E17: 45810 | F17: 45886 | G17: 45886 | H17: Lost | I17: 2 | J17: 20 | K17: 192000 | L17: 0 | M17: Competition | N17: =_xlfn.XLOOKUP(B17,tblCustomers[customer_id],tblCustomers[region],"Missing") -> West | O17: =_xlfn.XLOOKUP(C17,tblProducts[product_id],tblProducts[product_name],"Missing") -> CRM Essentials | P17: =_xlfn.XLOOKUP(C17,tblProducts[product_id],tblProducts[category],"Missing") -> CRM | Q17: =_xlfn.XLOOKUP(D17,tblSalesReps[rep_id],tblSalesReps[rep_name],"Missing") -> Sales Rep 11 | R17: =_xlfn.XLOOKUP(D17,tblSalesReps[rep_id],tblSalesReps[region],"Missing") -> West
A18: O00017 | B18: C0215 | C18: P005 | D18: R001 | E18: 45781 | F18: 45800 | G18: 45800 | H18: Won | I18: 3 | J18: 0 | K18: 540000 | L18: 100 | N18: =_xlfn.XLOOKUP(B18,tblCustomers[customer_id],tblCustomers[region],"Missing") -> South | O18: =_xlfn.XLOOKUP(C18,tblProducts[product_id],tblProducts[product_name],"Missing") -> Support Desk | P18: =_xlfn.XLOOKUP(C18,tblProducts[product_id],tblProducts[category],"Missing") -> Service | Q18: =_xlfn.XLOOKUP(D18,tblSalesReps[rep_id],tblSalesReps[rep_name],"Missing") -> Sales Rep 01 | R18: =_xlfn.XLOOKUP(D18,tblSalesReps[rep_id],tblSalesReps[region],"Missing") -> South
A19: O00018 | B19: C0112 | C19: P001 | D19: R007 | E19: 45915 | F19: 45951 | H19: Open | I19: 3 | J19: 10 | K19: 324000 | L19: 60 | N19: =_xlfn.XLOOKUP(B19,tblCustomers[customer_id],tblCustomers[region],"Missing") -> North | O19: =_xlfn.XLOOKUP(C19,tblProducts[product_id],tblProducts[product_name],"Missing") -> CRM Essentials | P19: =_xlfn.XLOOKUP(C19,tblProducts[product_id],tblProducts[category],"Missing") -> CRM | Q19: =_xlfn.XLOOKUP(D19,tblSalesReps[rep_id],tblSalesReps[rep_name],"Missing") -> Sales Rep 07 | R19: =_xlfn.XLOOKUP(D19,tblSalesReps[rep_id],tblSalesReps[region],"Missing") -> North
A20: O00019 | B20: C0286 | C20: P005 | D20: R012 | E20: 45978 | F20: 46056 | H20: Open | I20: 2 | J20: 0 | K20: 360000 | L20: 60 | N20: =_xlfn.XLOOKUP(B20,tblCustomers[customer_id],tblCustomers[region],"Missing") -> West | O20: =_xlfn.XLOOKUP(C20,tblProducts[product_id],tblProducts[product_name],"Missing") -> Support Desk | P20: =_xlfn.XLOOKUP(C20,tblProducts[product_id],tblProducts[category],"Missing") -> Service | Q20: =_xlfn.XLOOKUP(D20,tblSalesReps[rep_id],tblSalesReps[rep_name],"Missing") -> Sales Rep 12 | R20: =_xlfn.XLOOKUP(D20,tblSalesReps[rep_id],tblSalesReps[region],"Missing") -> West
A21: O00020 | B21: C0074 | C21: P004 | D21: R001 | E21: 45945 | F21: 46005 | G21: 46005 | H21: Lost | I21: 3 | J21: 20 | K21: 720000 | L21: 0 | M21: No decision | N21: =_xlfn.XLOOKUP(B21,tblCustomers[customer_id],tblCustomers[region],"Missing") -> South | O21: =_xlfn.XLOOKUP(C21,tblProducts[product_id],tblProducts[product_name],"Missing") -> Analytics Cloud | P21: =_xlfn.XLOOKUP(C21,tblProducts[product_id],tblProducts[category],"Missing") -> Analytics | Q21: =_xlfn.XLOOKUP(D21,tblSalesReps[rep_id],tblSalesReps[rep_name],"Missing") -> Sales Rep 01 | R21: =_xlfn.XLOOKUP(D21,tblSalesReps[rep_id],tblSalesReps[region],"Missing") -> South
A22: O00021 | B22: C0275 | C22: P006 | D22: R012 | E22: 45684 | F22: 45768 | G22: 45768 | H22: Won | I22: 3 | J22: 0 | K22: 1080000 | L22: 100 | N22: =_xlfn.XLOOKUP(B22,tblCustomers[customer_id],tblCustomers[region],"Missing") -> West | O22: =_xlfn.XLOOKUP(C22,tblProducts[product_id],tblProducts[product_name],"Missing") -> Security Suite | P22: =_xlfn.XLOOKUP(C22,tblProducts[product_id],tblProducts[category],"Missing") -> Security | Q22: =_xlfn.XLOOKUP(D22,tblSalesReps[rep_id],tblSalesReps[rep_name],"Missing") -> Sales Rep 12 | R22: =_xlfn.XLOOKUP(D22,tblSalesReps[rep_id],tblSalesReps[region],"Missing") -> West
A23: O00022 | B23: C0480 | C23: P002 | D23: R011 | E23: 45903 | F23: 45987 | H23: Open | I23: 1 | J23: 15 | K23: 357000 | L23: 40 | N23: =_xlfn.XLOOKUP(B23,tblCustomers[customer_id],tblCustomers[region],"Missing") -> West | O23: =_xlfn.XLOOKUP(C23,tblProducts[product_id],tblProducts[product_name],"Missing") -> CRM Enterprise | P23: =_xlfn.XLOOKUP(C23,tblProducts[product_id],tblProducts[category],"Missing") -> CRM | Q23: =_xlfn.XLOOKUP(D23,tblSalesReps[rep_id],tblSalesReps[rep_name],"Missing") -> Sales Rep 11 | R23: =_xlfn.XLOOKUP(D23,tblSalesReps[rep_id],tblSalesReps[region],"Missing") -> West
A24: O00023 | B24: C0412 | C24: P006 | D24: R014 | E24: 45821 | F24: 45875 | H24: Open | I24: 1 | J24: 15 | K24: 306000 | L24: 20 | N24: =_xlfn.XLOOKUP(B24,tblCustomers[customer_id],tblCustomers[region],"Missing") -> West | O24: =_xlfn.XLOOKUP(C24,tblProducts[product_id],tblProducts[product_name],"Missing") -> Security Suite | P24: =_xlfn.XLOOKUP(C24,tblProducts[product_id],tblProducts[category],"Missing") -> Security | Q24: =_xlfn.XLOOKUP(D24,tblSalesReps[rep_id],tblSalesReps[rep_name],"Missing") -> Sales Rep 14 | R24: =_xlfn.XLOOKUP(D24,tblSalesReps[rep_id],tblSalesReps[region],"Missing") -> West
A25: O00024 | B25: C0079 | C25: P002 | D25: R003 | E25: 45775 | F25: 45813 | G25: 45813 | H25: Lost | I25: 2 | J25: 20 | K25: 672000 | L25: 0 | M25: Budget | N25: =_xlfn.XLOOKUP(B25,tblCustomers[customer_id],tblCustomers[region],"Missing") -> South | O25: =_xlfn.XLOOKUP(C25,tblProducts[product_id],tblProducts[product_name],"Missing") -> CRM Enterprise | P25: =_xlfn.XLOOKUP(C25,tblProducts[product_id],tblProducts[category],"Missing") -> CRM | Q25: =_xlfn.XLOOKUP(D25,tblSalesReps[rep_id],tblSalesReps[rep_name],"Missing") -> Sales Rep 03 | R25: =_xlfn.XLOOKUP(D25,tblSalesReps[rep_id],tblSalesReps[region],"Missing") -> South
A26: O00025 | B26: C0025 | C26: P001 | D26: R019 | E26: 45728 | F26: 45764 | H26: Open | I26: 1 | J26: 5 | K26: 114000 | L26: 20 | N26: =_xlfn.XLOOKUP(B26,tblCustomers[customer_id],tblCustomers[region],"Missing") -> East | O26: =_xlfn.XLOOKUP(C26,tblProducts[product_id],tblProducts[product_name],"Missing") -> CRM Essentials | P26: =_xlfn.XLOOKUP(C26,tblProducts[product_id],tblProducts[category],"Missing") -> CRM | Q26: =_xlfn.XLOOKUP(D26,tblSalesReps[rep_id],tblSalesReps[rep_name],"Missing") -> Sales Rep 19 | R26: =_xlfn.XLOOKUP(D26,tblSalesReps[rep_id],tblSalesReps[region],"Missing") -> East
A27: O00026 | B27: C0004 | C27: P005 | D27: R005 | E27: 45868 | F27: 45942 | G27: 45942 | H27: Won | I27: 1 | J27: 20 | K27: 144000 | L27: 100 | N27: =_xlfn.XLOOKUP(B27,tblCustomers[customer_id],tblCustomers[region],"Missing") -> South | O27: =_xlfn.XLOOKUP(C27,tblProducts[product_id],tblProducts[product_name],"Missing") -> Support Desk | P27: =_xlfn.XLOOKUP(C27,tblProducts[product_id],tblProducts[category],"Missing") -> Service | Q27: =_xlfn.XLOOKUP(D27,tblSalesReps[rep_id],tblSalesReps[rep_name],"Missing") -> Sales Rep 05 | R27: =_xlfn.XLOOKUP(D27,tblSalesReps[rep_id],tblSalesReps[region],"Missing") -> South
A28: O00027 | B28: C0077 | C28: P002 | D28: R012 | E28: 45975 | F28: 46027 | H28: Open | I28: 1 | J28: 15 | K28: 357000 | L28: 20 | N28: =_xlfn.XLOOKUP(B28,tblCustomers[customer_id],tblCustomers[region],"Missing") -> West | O28: =_xlfn.XLOOKUP(C28,tblProducts[product_id],tblProducts[product_name],"Missing") -> CRM Enterprise | P28: =_xlfn.XLOOKUP(C28,tblProducts[product_id],tblProducts[category],"Missing") -> CRM | Q28: =_xlfn.XLOOKUP(D28,tblSalesReps[rep_id],tblSalesReps[rep_name],"Missing") -> Sales Rep 12 | R28: =_xlfn.XLOOKUP(D28,tblSalesReps[rep_id],tblSalesReps[region],"Missing") -> West
A29: O00028 | B29: C0208 | C29: P004 | D29: R004 | E29: 45940 | F29: 45948 | G29: 45948 | H29: Lost | I29: 1 | J29: 0 | K29: 300000 | L29: 0 | M29: No decision | N29: =_xlfn.XLOOKUP(B29,tblCustomers[customer_id],tblCustomers[region],"Missing") -> South | O29: =_xlfn.XLOOKUP(C29,tblProducts[product_id],tblProducts[product_name],"Missing") -> Analytics Cloud | P29: =_xlfn.XLOOKUP(C29,tblProducts[product_id],tblProducts[category],"Missing") -> Analytics | Q29: =_xlfn.XLOOKUP(D29,tblSalesReps[rep_id],tblSalesReps[rep_name],"Missing") -> Sales Rep 04 | R29: =_xlfn.XLOOKUP(D29,tblSalesReps[rep_id],tblSalesReps[region],"Missing") -> South
A30: O00029 | B30: C0289 | C30: P006 | D30: R011 | E30: 45749 | F30: 45796 | H30: Open | I30: 1 | J30: 5 | K30: 342000 | L30: 40 | N30: =_xlfn.XLOOKUP(B30,tblCustomers[customer_id],tblCustomers[region],"Missing") -> West | O30: =_xlfn.XLOOKUP(C30,tblProducts[product_id],tblProducts[product_name],"Missing") -> Security Suite | P30: =_xlfn.XLOOKUP(C30,tblProducts[product_id],tblProducts[category],"Missing") -> Security | Q30: =_xlfn.XLOOKUP(D30,tblSalesReps[rep_id],tblSalesReps[rep_name],"Missing") -> Sales Rep 11 | R30: =_xlfn.XLOOKUP(D30,tblSalesReps[rep_id],tblSalesReps[region],"Missing") -> West
A31: O00030 | B31: C0382 | C31: P003 | D31: R011 | E31: 45708 | F31: 45724 | G31: 45724 | H31: Lost | I31: 1 | J31: 20 | K31: 192000 | L31: 0 | M31: Budget | N31: =_xlfn.XLOOKUP(B31,tblCustomers[customer_id],tblCustomers[region],"Missing") -> West | O31: =_xlfn.XLOOKUP(C31,tblProducts[product_id],tblProducts[product_name],"Missing") -> Workflow Automate | P31: =_xlfn.XLOOKUP(C31,tblProducts[product_id],tblProducts[category],"Missing") -> Automation | Q31: =_xlfn.XLOOKUP(D31,tblSalesReps[rep_id],tblSalesReps[rep_name],"Missing") -> Sales Rep 11 | R31: =_xlfn.XLOOKUP(D31,tblSalesReps[rep_id],tblSalesReps[region],"Missing") -> West
A32: O00031 | B32: C0482 | C32: P004 | D32: R014 | E32: 45753 | F32: 45808 | G32: 45808 | H32: Lost | I32: 1 | J32: 20 | K32: 240000 | L32: 0 | M32: Competition | N32: =_xlfn.XLOOKUP(B32,tblCustomers[customer_id],tblCustomers[region],"Missing") -> West | O32: =_xlfn.XLOOKUP(C32,tblProducts[product_id],tblProducts[product_name],"Missing") -> Analytics Cloud | P32: =_xlfn.XLOOKUP(C32,tblProducts[product_id],tblProducts[category],"Missing") -> Analytics | Q32: =_xlfn.XLOOKUP(D32,tblSalesReps[rep_id],tblSalesReps[rep_name],"Missing") -> Sales Rep 14 | R32: =_xlfn.XLOOKUP(D32,tblSalesReps[rep_id],tblSalesReps[region],"Missing") -> West
A33: O00032 | B33: C0200 | C33: P003 | D33: R008 | E33: 45712 | F33: 45758 | G33: 45758 | H33: Won | I33: 2 | J33: 10 | K33: 432000 | L33: 100 | N33: =_xlfn.XLOOKUP(B33,tblCustomers[customer_id],tblCustomers[region],"Missing") -> North | O33: =_xlfn.XLOOKUP(C33,tblProducts[product_id],tblProducts[product_name],"Missing") -> Workflow Automate | P33: =_xlfn.XLOOKUP(C33,tblProducts[product_id],tblProducts[category],"Missing") -> Automation | Q33: =_xlfn.XLOOKUP(D33,tblSalesReps[rep_id],tblSalesReps[rep_name],"Missing") -> Sales Rep 08 | R33: =_xlfn.XLOOKUP(D33,tblSalesReps[rep_id],tblSalesReps[region],"Missing") -> North
A34: O00033 | B34: C0285 | C34: P005 | D34: R009 | E34: 45710 | F34: 45762 | G34: 45762 | H34: Won | I34: 3 | J34: 0 | K34: 540000 | L34: 100 | N34: =_xlfn.XLOOKUP(B34,tblCustomers[customer_id],tblCustomers[region],"Missing") -> North | O34: =_xlfn.XLOOKUP(C34,tblProducts[product_id],tblProducts[product_name],"Missing") -> Support Desk | P34: =_xlfn.XLOOKUP(C34,tblProducts[product_id],tblProducts[category],"Missing") -> Service | Q34: =_xlfn.XLOOKUP(D34,tblSalesReps[rep_id],tblSalesReps[rep_name],"Missing") -> Sales Rep 09 | R34: =_xlfn.XLOOKUP(D34,tblSalesReps[rep_id],tblSalesReps[region],"Missing") -> North
A35: O00034 | B35: C0138 | C35: P003 | D35: R008 | E35: 45910 | F35: 45938 | G35: 45938 | H35: Won | I35: 2 | J35: 10 | K35: 432000 | L35: 100 | N35: =_xlfn.XLOOKUP(B35,tblCustomers[customer_id],tblCustomers[region],"Missing") -> North | O35: =_xlfn.XLOOKUP(C35,tblProducts[product_id],tblProducts[product_name],"Missing") -> Workflow Automate | P35: =_xlfn.XLOOKUP(C35,tblProducts[product_id],tblProducts[category],"Missing") -> Automation | Q35: =_xlfn.XLOOKUP(D35,tblSalesReps[rep_id],tblSalesReps[rep_name],"Missing") -> Sales Rep 08 | R35: =_xlfn.XLOOKUP(D35,tblSalesReps[rep_id],tblSalesReps[region],"Missing") -> North
A36: O00035 | B36: C0055 | C36: P002 | D36: R013 | E36: 45661 | F36: 45710 | H36: Open | I36: 3 | J36: 15 | K36: 1071000 | L36: 60 | N36: =_xlfn.XLOOKUP(B36,tblCustomers[customer_id],tblCustomers[region],"Missing") -> West | O36: =_xlfn.XLOOKUP(C36,tblProducts[product_id],tblProducts[product_name],"Missing") -> CRM Enterprise | P36: =_xlfn.XLOOKUP(C36,tblProducts[product_id],tblProducts[category],"Missing") -> CRM | Q36: =_xlfn.XLOOKUP(D36,tblSalesReps[rep_id],tblSalesReps[rep_name],"Missing") -> Sales Rep 13 | R36: =_xlfn.XLOOKUP(D36,tblSalesReps[rep_id],tblSalesReps[region],"Missing") -> West
A37: O00036 | B37: C0150 | C37: P006 | D37: R019 | E37: 45952 | F37: 46000 | H37: Open | I37: 2 | J37: 10 | K37: 648000 | L37: 80 | N37: =_xlfn.XLOOKUP(B37,tblCustomers[customer_id],tblCustomers[region],"Missing") -> East | O37: =_xlfn.XLOOKUP(C37,tblProducts[product_id],tblProducts[product_name],"Missing") -> Security Suite | P37: =_xlfn.XLOOKUP(C37,tblProducts[product_id],tblProducts[category],"Missing") -> Security | Q37: =_xlfn.XLOOKUP(D37,tblSalesReps[rep_id],tblSalesReps[rep_name],"Missing") -> Sales Rep 19 | R37: =_xlfn.XLOOKUP(D37,tblSalesReps[rep_id],tblSalesReps[region],"Missing") -> East
A38: O00037 | B38: C0108 | C38: P004 | D38: R003 | E38: 46012 | F38: 46071 | H38: Open | I38: 2 | J38: 5 | K38: 570000 | L38: 60 | N38: =_xlfn.XLOOKUP(B38,tblCustomers[customer_id],tblCustomers[region],"Missing") -> South | O38: =_xlfn.XLOOKUP(C38,tblProducts[product_id],tblProducts[product_name],"Missing") -> Analytics Cloud | P38: =_xlfn.XLOOKUP(C38,tblProducts[product_id],tblProducts[category],"Missing") -> Analytics | Q38: =_xlfn.XLOOKUP(D38,tblSalesReps[rep_id],tblSalesReps[rep_name],"Missing") -> Sales Rep 03 | R38: =_xlfn.XLOOKUP(D38,tblSalesReps[rep_id],tblSalesReps[region],"Missing") -> South
A39: O00038 | B39: C0299 | C39: P004 | D39: R010 | E39: 45917 | F39: 45977 | H39: Open | I39: 3 | J39: 0 | K39: 900000 | L39: 60 | N39: =_xlfn.XLOOKUP(B39,tblCustomers[customer_id],tblCustomers[region],"Missing") -> North | O39: =_xlfn.XLOOKUP(C39,tblProducts[product_id],tblProducts[product_name],"Missing") -> Analytics Cloud | P39: =_xlfn.XLOOKUP(C39,tblProducts[product_id],tblProducts[category],"Missing") -> Analytics | Q39: =_xlfn.XLOOKUP(D39,tblSalesReps[rep_id],tblSalesReps[rep_name],"Missing") -> Sales Rep 10 | R39: =_xlfn.XLOOKUP(D39,tblSalesReps[rep_id],tblSalesReps[region],"Missing") -> North
A40: O00039 | B40: C0332 | C40: P005 | D40: R001 | E40: 45946 | F40: 46004 | H40: Open | I40: 1 | J40: 15 | K40: 153000 | L40: 20 | N40: =_xlfn.XLOOKUP(B40,tblCustomers[customer_id],tblCustomers[region],"Missing") -> South | O40: =_xlfn.XLOOKUP(C40,tblProducts[product_id],tblProducts[product_name],"Missing") -> Support Desk | P40: =_xlfn.XLOOKUP(C40,tblProducts[product_id],tblProducts[category],"Missing") -> Service | Q40: =_xlfn.XLOOKUP(D40,tblSalesReps[rep_id],tblSalesReps[rep_name],"Missing") -> Sales Rep 01 | R40: =_xlfn.XLOOKUP(D40,tblSalesReps[rep_id],tblSalesReps[region],"Missing") -> South
...

Sheet Validation
B1: =COUNTIF(tblOpportunities[Customer Region],"Missing") -> 0
B2: =COUNTIF(tblOpportunities[Product Name],"Missing") -> 0
B3: =COUNTIF(tblOpportunities[Product Category],"Missing") -> 0
B4: =COUNTIF(tblOpportunities[Sales Rep Name],"Missing") -> 0
B5: =COUNTIF(tblOpportunities[Sales Rep Region],"Missing") -> 0

Sheet KPI_Analysis
A1: Revenue & Sales Operations Intelligence
A3: KPI Metric | B3: Value
A4: Total Opportunities | B4: =COUNTA(tblOpportunities[opportunity_id]) -> 3000
A5: Won Opportunities | B5: =COUNTIF(tblOpportunities[stage],"Won") -> 907
A6: Lost Opportunities | B6: =COUNTIF(tblOpportunities[stage],"Lost") -> 1067
A7: Open Opportunities | B7: =COUNTIF(tblOpportunities[stage],"Open") -> 1026
A8: Win Rate | B8: =IFERROR(B5/(B5+B6),0) -> 0.45947315
A9: Total Won Revenue | B9: =SUMIF(tblOpportunities[stage],"Won",tblOpportunities[deal_value_inr]) -> 343497000
A10: Average Won Deal Value | B10: =IFERROR(B9/B5,0) -> 378717.75
A11: Open Pipeline Value | B11: =SUMIF(tblOpportunities[stage],"Open",tblOpportunities[deal_value_inr]) -> 388227000
A12: Weighted Open Pipeline | B12: {=SUMPRODUCT((tblOpportunities[stage]="Open")*tblOpportunities[deal_value_inr]*tblOpportunities[probability_pct]/100)} -> 191400600
